<?xml version="1.0" ?>
<robot name="manipulator" xmlns:xacro="http://www.ros.org/wiki/xacro">

<xacro:include filename="$(find manipulator_description)/urdf/materials.xacro" />
<xacro:include filename="$(find manipulator_description)/urdf/manipulator.trans" />
<xacro:include filename="$(find manipulator_description)/urdf/manipulator.gazebo" />
<link name="base_link">
  <inertial>
    <origin rpy="0 0 0" xyz="-0.001421101933510318 -4.6483972785353857e-07 0.001499999999999997"/>
    <mass value="0.16048002164494451"/>
    <inertia ixx="0.000113" ixy="0.0" ixz="0.0" iyy="0.000107" iyz="-0.0" izz="0.000219"/>
  </inertial>
  <visual>
    <origin rpy="0 0 0" xyz="0 0 0"/>
    <geometry>
      <mesh filename="package://manipulator_description/meshes/base_link.stl" scale="0.001 0.001 0.001"/>
    </geometry>
    <material name="silver"/>
  </visual>
  <collision>
    <origin rpy="0 0 0" xyz="0 0 0"/>
    <geometry>
      <mesh filename="package://manipulator_description/meshes/base_link.stl" scale="0.001 0.001 0.001"/>
    </geometry>
  </collision>
</link>

<link name="S3003_v3_1">
  <inertial>
    <origin rpy="0 0 0" xyz="0.024427603744671927 -0.0050248460466941125 -0.00807973154549043"/>
    <mass value="0.23401442553734317"/>
    <inertia ixx="3.5e-05" ixy="-0.0" ixz="1e-06" iyy="6e-05" iyz="-0.0" izz="4e-05"/>
  </inertial>
  <visual>
    <origin rpy="0 0 0" xyz="0.0141 -0.005025 -0.003"/>
    <geometry>
      <mesh filename="package://manipulator_description/meshes/S3003_v3_1.stl" scale="0.001 0.001 0.001"/>
    </geometry>
    <material name="silver"/>
  </visual>
  <collision>
    <origin rpy="0 0 0" xyz="0.0141 -0.005025 -0.003"/>
    <geometry>
      <mesh filename="package://manipulator_description/meshes/S3003_v3_1.stl" scale="0.001 0.001 0.001"/>
    </geometry>
  </collision>
</link>

<link name="base_linkz_v1_1">
  <inertial>
    <origin rpy="0 0 0" xyz="1.8717896266108107e-05 1.8896593900126008e-05 -0.00820968106488855"/>
    <mass value="0.19906890879785208"/>
    <inertia ixx="6.9e-05" ixy="0.0" ixz="-0.0" iyy="0.000123" iyz="-0.0" izz="0.000154"/>
  </inertial>
  <visual>
    <origin rpy="0 0 0" xyz="-0.0 0.0 -0.03838"/>
    <geometry>
      <mesh filename="package://manipulator_description/meshes/base_linkz_v1_1.stl" scale="0.001 0.001 0.001"/>
    </geometry>
    <material name="silver"/>
  </visual>
  <collision>
    <origin rpy="0 0 0" xyz="-0.0 0.0 -0.03838"/>
    <geometry>
      <mesh filename="package://manipulator_description/meshes/base_linkz_v1_1.stl" scale="0.001 0.001 0.001"/>
    </geometry>
  </collision>
</link>

<link name="S3003_v3__1__1">
  <inertial>
    <origin rpy="0 0 0" xyz="0.009572396255328144 -0.022329731545490398 -0.02721484604669415"/>
    <mass value="0.23401442553734317"/>
    <inertia ixx="3.5e-05" ixy="-1e-06" ixz="0.0" iyy="4e-05" iyz="-0.0" izz="6e-05"/>
  </inertial>
  <visual>
    <origin rpy="0 0 0" xyz="0.01 -0.02425 -0.06938"/>
    <geometry>
      <mesh filename="package://manipulator_description/meshes/S3003_v3__1__1.stl" scale="0.001 0.001 0.001"/>
    </geometry>
    <material name="silver"/>
  </visual>
  <collision>
    <origin rpy="0 0 0" xyz="0.01 -0.02425 -0.06938"/>
    <geometry>
      <mesh filename="package://manipulator_description/meshes/S3003_v3__1__1.stl" scale="0.001 0.001 0.001"/>
    </geometry>
  </collision>
</link>

<link name="link_v3_1">
  <inertial>
    <origin rpy="0 0 0" xyz="-0.031025375618104985 -0.06232217764752555 0.03053657812083671"/>
    <mass value="0.14389975561434148"/>
    <inertia ixx="0.000157" ixy="-1e-06" ixz="8e-06" iyy="0.000114" iyz="6e-06" izz="6e-05"/>
  </inertial>
  <visual>
    <origin rpy="0 0 0" xyz="-0.03609 -0.068355 -0.052065"/>
    <geometry>
      <mesh filename="package://manipulator_description/meshes/link_v3_1.stl" scale="0.001 0.001 0.001"/>
    </geometry>
    <material name="silver"/>
  </visual>
  <collision>
    <origin rpy="0 0 0" xyz="-0.03609 -0.068355 -0.052065"/>
    <geometry>
      <mesh filename="package://manipulator_description/meshes/link_v3_1.stl" scale="0.001 0.001 0.001"/>
    </geometry>
  </collision>
</link>

<link name="S3003_v3__2__1">
  <inertial>
    <origin rpy="0 0 0" xyz="0.008714846046694223 -0.007979731545490417 -0.12034260374467196"/>
    <mass value="0.23401442553734317"/>
    <inertia ixx="6e-05" ixy="0.0" ixz="-0.0" iyy="4e-05" iyz="-1e-06" izz="3.5e-05"/>
  </inertial>
  <visual>
    <origin rpy="0 0 0" xyz="-0.00121 -0.00809 -0.23708"/>
    <geometry>
      <mesh filename="package://manipulator_description/meshes/S3003_v3__2__1.stl" scale="0.001 0.001 0.001"/>
    </geometry>
    <material name="silver"/>
  </visual>
  <collision>
    <origin rpy="0 0 0" xyz="-0.00121 -0.00809 -0.23708"/>
    <geometry>
      <mesh filename="package://manipulator_description/meshes/S3003_v3__2__1.stl" scale="0.001 0.001 0.001"/>
    </geometry>
  </collision>
</link>

<link name="link_v3__1__1">
  <inertial>
    <origin rpy="0 0 0" xyz="0.005089624381894951 -0.14722217764752554 0.016056578120836718"/>
    <mass value="0.14389975561434148"/>
    <inertia ixx="0.000157" ixy="-1e-06" ixz="8e-06" iyy="0.000114" iyz="6e-06" izz="6e-05"/>
  </inertial>
  <visual>
    <origin rpy="0 0 0" xyz="0.0 -0.151445 -0.151445"/>
    <geometry>
      <mesh filename="package://manipulator_description/meshes/link_v3__1__1.stl" scale="0.001 0.001 0.001"/>
    </geometry>
    <material name="silver"/>
  </visual>
  <collision>
    <origin rpy="0 0 0" xyz="0.0 -0.151445 -0.151445"/>
    <geometry>
      <mesh filename="package://manipulator_description/meshes/link_v3__1__1.stl" scale="0.001 0.001 0.001"/>
    </geometry>
  </collision>
</link>

<link name="S3003_v3__3__1">
  <inertial>
    <origin rpy="0 0 0" xyz="0.0069048460466941694 -0.008004731545490376 -0.20524260374467185"/>
    <mass value="0.23401442553734317"/>
    <inertia ixx="6e-05" ixy="0.0" ixz="-0.0" iyy="4e-05" iyz="-1e-06" izz="3.5e-05"/>
  </inertial>
  <visual>
    <origin rpy="0 0 0" xyz="-0.003045 -0.006305 -0.40688"/>
    <geometry>
      <mesh filename="package://manipulator_description/meshes/S3003_v3__3__1.stl" scale="0.001 0.001 0.001"/>
    </geometry>
    <material name="silver"/>
  </visual>
  <collision>
    <origin rpy="0 0 0" xyz="-0.003045 -0.006305 -0.40688"/>
    <geometry>
      <mesh filename="package://manipulator_description/meshes/S3003_v3__3__1.stl" scale="0.001 0.001 0.001"/>
    </geometry>
  </collision>
</link>

<link name="hand_left_branch_v1_1">
  <inertial>
    <origin rpy="0 0 0" xyz="-0.0015316842729150952 0.0023733048413085676 0.003579692747881169"/>
    <mass value="0.015405522957269007"/>
    <inertia ixx="3e-06" ixy="0.0" ixz="0.0" iyy="2e-06" iyz="-1e-06" izz="1e-06"/>
  </inertial>
  <visual>
    <origin rpy="0 0 0" xyz="-0.01745 -0.015642 -0.274965"/>
    <geometry>
      <mesh filename="package://manipulator_description/meshes/hand_left_branch_v1_1.stl" scale="0.001 0.001 0.001"/>
    </geometry>
    <material name="silver"/>
  </visual>
  <collision>
    <origin rpy="0 0 0" xyz="-0.01745 -0.015642 -0.274965"/>
    <geometry>
      <mesh filename="package://manipulator_description/meshes/hand_left_branch_v1_1.stl" scale="0.001 0.001 0.001"/>
    </geometry>
  </collision>
</link>

<link name="hand_left_branch_child_v1_1">
  <inertial>
    <origin rpy="0 0 0" xyz="-0.0016214666378756952 0.007028174244609985 0.014659420900538955"/>
    <mass value="0.004018492615889962"/>
    <inertia ixx="0.0" ixy="0.0" ixz="0.0" iyy="0.0" iyz="-0.0" izz="0.0"/>
  </inertial>
  <visual>
    <origin rpy="0 0 0" xyz="-0.01745 -0.010634 -0.293426"/>
    <geometry>
      <mesh filename="package://manipulator_description/meshes/hand_left_branch_child_v1_1.stl" scale="0.001 0.001 0.001"/>
    </geometry>
    <material name="silver"/>
  </visual>
  <collision>
    <origin rpy="0 0 0" xyz="-0.01745 -0.010634 -0.293426"/>
    <geometry>
      <mesh filename="package://manipulator_description/meshes/hand_left_branch_child_v1_1.stl" scale="0.001 0.001 0.001"/>
    </geometry>
  </collision>
</link>

<link name="hand_right_branch_child_v1_1">
  <inertial>
    <origin rpy="0 0 0" xyz="-0.0016214666419173684 -0.007028894224718479 0.014659420901202813"/>
    <mass value="0.004018492615889964"/>
    <inertia ixx="0.0" ixy="-0.0" ixz="0.0" iyy="0.0" iyz="0.0" izz="0.0"/>
  </inertial>
  <visual>
    <origin rpy="0 0 0" xyz="-0.01745 0.00695 -0.293426"/>
    <geometry>
      <mesh filename="package://manipulator_description/meshes/hand_right_branch_child_v1_1.stl" scale="0.001 0.001 0.001"/>
    </geometry>
    <material name="silver"/>
  </visual>
  <collision>
    <origin rpy="0 0 0" xyz="-0.01745 0.00695 -0.293426"/>
    <geometry>
      <mesh filename="package://manipulator_description/meshes/hand_right_branch_child_v1_1.stl" scale="0.001 0.001 0.001"/>
    </geometry>
  </collision>
</link>

<link name="finger_v1_1">
  <inertial>
    <origin rpy="0 0 0" xyz="0.003000000000265927 -0.006568383614959955 0.022853859000569077"/>
    <mass value="0.04016093181165222"/>
    <inertia ixx="1.1e-05" ixy="0.0" ixz="0.0" iyy="1.2e-05" iyz="1e-06" izz="1e-06"/>
  </inertial>
  <visual>
    <origin rpy="0 0 0" xyz="-0.01165 -0.032142 -0.303544"/>
    <geometry>
      <mesh filename="package://manipulator_description/meshes/finger_v1_1.stl" scale="0.001 0.001 0.001"/>
    </geometry>
    <material name="silver"/>
  </visual>
  <collision>
    <origin rpy="0 0 0" xyz="-0.01165 -0.032142 -0.303544"/>
    <geometry>
      <mesh filename="package://manipulator_description/meshes/finger_v1_1.stl" scale="0.001 0.001 0.001"/>
    </geometry>
  </collision>
</link>

<link name="finger_v1__1__1">
  <inertial>
    <origin rpy="0 0 0" xyz="0.002999999994448577 0.0015596636366701257 0.004392859002138649"/>
    <mass value="0.04016093181165222"/>
    <inertia ixx="1.1e-05" ixy="0.0" ixz="-0.0" iyy="1.2e-05" iyz="-1e-06" izz="1e-06"/>
  </inertial>
  <visual>
    <origin rpy="0 0 0" xyz="-0.01165 0.02345 -0.322005"/>
    <geometry>
      <mesh filename="package://manipulator_description/meshes/finger_v1__1__1.stl" scale="0.001 0.001 0.001"/>
    </geometry>
    <material name="silver"/>
  </visual>
  <collision>
    <origin rpy="0 0 0" xyz="-0.01165 0.02345 -0.322005"/>
    <geometry>
      <mesh filename="package://manipulator_description/meshes/finger_v1__1__1.stl" scale="0.001 0.001 0.001"/>
    </geometry>
  </collision>
</link>

<link name="finger_v1_1">
  <inertial>
    <origin rpy="0 0 0" xyz="0.003000000000265927 -0.0015603836149599565 0.0043928590005690715"/>
    <mass value="0.04016093181165222"/>
    <inertia ixx="1.1e-05" ixy="0.0" ixz="0.0" iyy="1.2e-05" iyz="1e-06" izz="1e-06"/>
  </inertial>
  <visual>
    <origin rpy="0 0 0" xyz="-0.01165 -0.027134 -0.322005"/>
    <geometry>
      <mesh filename="package://manipulator_description/meshes/finger_v1_1.stl" scale="0.001 0.001 0.001"/>
    </geometry>
    <material name="silver"/>
  </visual>
  <collision>
    <origin rpy="0 0 0" xyz="-0.01165 -0.027134 -0.322005"/>
    <geometry>
      <mesh filename="package://manipulator_description/meshes/finger_v1_1.stl" scale="0.001 0.001 0.001"/>
    </geometry>
  </collision>
</link>

<link name="hand_CM_indirect_v1_1">
  <inertial>
    <origin rpy="0 0 0" xyz="-0.001990457089223612 -3.8014542655569195e-07 1.7657288275962912e-07"/>
    <mass value="0.013860189452301722"/>
    <inertia ixx="0.0" ixy="-0.0" ixz="-0.0" iyy="0.0" iyz="-0.0" izz="0.0"/>
  </inertial>
  <visual>
    <origin rpy="0 0 0" xyz="-0.02145 0.009347 -0.254986"/>
    <geometry>
      <mesh filename="package://manipulator_description/meshes/hand_CM_indirect_v1_1.stl" scale="0.001 0.001 0.001"/>
    </geometry>
    <material name="silver"/>
  </visual>
  <collision>
    <origin rpy="0 0 0" xyz="-0.02145 0.009347 -0.254986"/>
    <geometry>
      <mesh filename="package://manipulator_description/meshes/hand_CM_indirect_v1_1.stl" scale="0.001 0.001 0.001"/>
    </geometry>
  </collision>
</link>

<link name="hand_front_v1_1">
  <inertial>
    <origin rpy="0 0 0" xyz="0.0007987520764846066 -0.004323888300032726 -0.03787661953322019"/>
    <mass value="0.15370051173121926"/>
    <inertia ixx="0.000156" ixy="0.0" ixz="6e-06" iyy="0.000103" iyz="-5e-06" izz="5.9e-05"/>
  </inertial>
  <visual>
    <origin rpy="0 0 0" xyz="-0.00745 -0.002842 -0.290965"/>
    <geometry>
      <mesh filename="package://manipulator_description/meshes/hand_front_v1_1.stl" scale="0.001 0.001 0.001"/>
    </geometry>
    <material name="silver"/>
  </visual>
  <collision>
    <origin rpy="0 0 0" xyz="-0.00745 -0.002842 -0.290965"/>
    <geometry>
      <mesh filename="package://manipulator_description/meshes/hand_front_v1_1.stl" scale="0.001 0.001 0.001"/>
    </geometry>
  </collision>
</link>

<link name="S3003_v3__3__1">
  <inertial>
    <origin rpy="0 0 0" xyz="0.20446484604669415 0.022300268454509622 -0.0563016037446718"/>
    <mass value="0.23401442553734317"/>
    <inertia ixx="6e-05" ixy="0.0" ixz="-0.0" iyy="4e-05" iyz="-1e-06" izz="3.5e-05"/>
  </inertial>
  <visual>
    <origin rpy="0 0 0" xyz="0.194515 0.024 -0.257939"/>
    <geometry>
      <mesh filename="package://manipulator_description/meshes/S3003_v3__3__1.stl" scale="0.001 0.001 0.001"/>
    </geometry>
    <material name="silver"/>
  </visual>
  <collision>
    <origin rpy="0 0 0" xyz="0.194515 0.024 -0.257939"/>
    <geometry>
      <mesh filename="package://manipulator_description/meshes/S3003_v3__3__1.stl" scale="0.001 0.001 0.001"/>
    </geometry>
  </collision>
</link>

<link name="hand_back_v1_1">
  <inertial>
    <origin rpy="0 0 0" xyz="0.0019176434120333173 0.013977283722594889 -0.003983921774310062"/>
    <mass value="0.07394116010800626"/>
    <inertia ixx="3.7e-05" ixy="0.0" ixz="0.0" iyy="1.6e-05" iyz="-0.0" izz="2.1e-05"/>
  </inertial>
  <visual>
    <origin rpy="0 0 0" xyz="-0.01745 0.011958 -0.274965"/>
    <geometry>
      <mesh filename="package://manipulator_description/meshes/hand_back_v1_1.stl" scale="0.001 0.001 0.001"/>
    </geometry>
    <material name="silver"/>
  </visual>
  <collision>
    <origin rpy="0 0 0" xyz="-0.01745 0.011958 -0.274965"/>
    <geometry>
      <mesh filename="package://manipulator_description/meshes/hand_back_v1_1.stl" scale="0.001 0.001 0.001"/>
    </geometry>
  </collision>
</link>

<link name="hand_right_branch_v2_1">
  <inertial>
    <origin rpy="0 0 0" xyz="0.0042687589535156355 0.014240709796650732 -0.025197665977341244"/>
    <mass value="0.015624087959943174"/>
    <inertia ixx="3e-06" ixy="-0.0" ixz="0.0" iyy="2e-06" iyz="1e-06" izz="1e-06"/>
  </inertial>
  <visual>
    <origin rpy="0 0 0" xyz="-0.01165 0.028458 -0.303544"/>
    <geometry>
      <mesh filename="package://manipulator_description/meshes/hand_right_branch_v2_1.stl" scale="0.001 0.001 0.001"/>
    </geometry>
    <material name="silver"/>
  </visual>
  <collision>
    <origin rpy="0 0 0" xyz="-0.01165 0.028458 -0.303544"/>
    <geometry>
      <mesh filename="package://manipulator_description/meshes/hand_right_branch_v2_1.stl" scale="0.001 0.001 0.001"/>
    </geometry>
  </collision>
</link>

<joint name="Rigid3" type="fixed">
  <origin rpy="0 0 0" xyz="-0.0141 0.005025 0.003"/>
  <parent link="base_link"/>
  <child link="S3003_v3_1"/>
</joint>

<joint name="Rev4" type="continuous">
  <origin rpy="0 0 0" xyz="0.0141 -0.005025 0.03538"/>
  <parent link="S3003_v3_1"/>
  <child link="base_linkz_v1_1"/>
  <axis xyz="-0.0 -0.0 1.0"/>
</joint>

<joint name="Rigid5" type="fixed">
  <origin rpy="0 0 0" xyz="-0.01 0.02425 0.031"/>
  <parent link="base_linkz_v1_1"/>
  <child link="S3003_v3__1__1"/>
</joint>

<joint name="Rev6" type="continuous">
  <origin rpy="0 0 0" xyz="0.04609 0.044105 -0.017315"/>
  <parent link="S3003_v3__1__1"/>
  <child link="link_v3_1"/>
  <axis xyz="0.0 1.0 -0.0"/>
</joint>

<joint name="Rigid7" type="fixed">
  <origin rpy="0 0 0" xyz="-0.03488 -0.060265 0.185015"/>
  <parent link="link_v3_1"/>
  <child link="S3003_v3__2__1"/>
</joint>

<joint name="Rev8" type="continuous">
  <origin rpy="0 0 0" xyz="-0.00121 0.143355 -0.085635"/>
  <parent link="S3003_v3__2__1"/>
  <child link="link_v3__1__1"/>
  <axis xyz="-0.0 1.0 0.0"/>
</joint>

<joint name="Rigid9" type="fixed">
  <origin rpy="0 0 0" xyz="-0.194515 -0.175445 0.106494"/>
  <parent link="link_v3__1__1"/>
  <child link="S3003_v3__3__1"/>
</joint>

<joint name="Rev11" type="continuous">
  <origin rpy="0 0 0" xyz="0.0 0.0276 0.0"/>
  <parent link="hand_back_v1_1"/>
  <child link="hand_left_branch_v1_1"/>
  <axis xyz="-1.0 0.0 0.0"/>
</joint>

<joint name="Rev13" type="continuous">
  <origin rpy="0 0 0" xyz="0.0 0.022592 0.018461"/>
  <parent link="hand_back_v1_1"/>
  <child link="hand_left_branch_child_v1_1"/>
  <axis xyz="-1.0 0.0 0.0"/>
</joint>

<joint name="Rev14" type="continuous">
  <origin rpy="0 0 0" xyz="0.0 0.005008 0.018461"/>
  <parent link="hand_back_v1_1"/>
  <child link="hand_right_branch_child_v1_1"/>
  <axis xyz="-1.0 0.0 0.0"/>
</joint>

<joint name="Rev15" type="continuous">
  <origin rpy="0 0 0" xyz="-0.0058 0.011492 0.04704"/>
  <parent link="hand_left_branch_v1_1"/>
  <child link="finger_v1_1"/>
  <axis xyz="-1.0 0.0 0.0"/>
</joint>

<joint name="Rev17" type="continuous">
  <origin rpy="0 0 0" xyz="-0.0058 -0.0165 0.028579"/>
  <parent link="hand_right_branch_child_v1_1"/>
  <child link="finger_v1__1__1"/>
  <axis xyz="-1.0 0.0 0.0"/>
</joint>

<joint name="Rev18" type="continuous">
  <origin rpy="0 0 0" xyz="-0.0058 0.0165 0.028579"/>
  <parent link="hand_left_branch_child_v1_1"/>
  <child link="finger_v1_1"/>
  <axis xyz="-1.0 0.0 0.0"/>
</joint>

<joint name="Rev19" type="continuous">
  <origin rpy="0 0 0" xyz="0.004 0.002611 -0.019979"/>
  <parent link="hand_back_v1_1"/>
  <child link="hand_CM_indirect_v1_1"/>
  <axis xyz="1.0 -0.0 -0.0"/>
</joint>

<joint name="Rigid20" type="fixed">
  <origin rpy="0 0 0" xyz="-0.01 0.0148 0.016"/>
  <parent link="hand_back_v1_1"/>
  <child link="hand_front_v1_1"/>
</joint>

<joint name="Rev10" type="continuous">
  <origin rpy="0 0 0" xyz="-0.201965 -0.026842 -0.033026"/>
  <parent link="hand_front_v1_1"/>
  <child link="S3003_v3__3__1"/>
  <axis xyz="-0.0 -1.0 -0.0"/>
</joint>

<joint name="Rev22" type="continuous">
  <origin rpy="0 0 0" xyz="0.0058 0.0165 -0.028579"/>
  <parent link="hand_right_branch_v2_1"/>
  <child link="hand_back_v1_1"/>
  <axis xyz="1.0 -0.0 -0.0"/>
</joint>

<joint name="Rev23" type="continuous">
  <origin rpy="0 0 0" xyz="0.0 -0.005008 -0.018461"/>
  <parent link="finger_v1__1__1"/>
  <child link="hand_right_branch_v2_1"/>
  <axis xyz="-1.0 0.0 0.0"/>
</joint>

</robot>
