<?xml version="1.0" ?>
<robot name="manipulator" xmlns:xacro="http://www.ros.org/wiki/xacro">

<xacro:include filename="$(find manipulator_description)/urdf/materials.xacro" />
<xacro:include filename="$(find manipulator_description)/urdf/manipulator.trans" />
<xacro:include filename="$(find manipulator_description)/urdf/manipulator.gazebo" />
<link name="base_link">
  <inertial>
    <origin rpy="0 0 0" xyz="-4.648397278535995e-07 0.0014211019335103174 0.001499999999999997"/>
    <mass value="0.16048002164494451"/>
    <inertia ixx="0.000107" ixy="-0.0" ixz="-0.0" iyy="0.000113" iyz="-0.0" izz="0.000219"/>
  </inertial>
  <visual>
    <origin rpy="0 0 0" xyz="0 0 0"/>
    <geometry>
      <mesh filename="package://manipulator_description/meshes/base_link.stl" scale="0.001 0.001 0.001"/>
    </geometry>
    <material name="silver_default"/>
  </visual>
  <collision>
    <origin rpy="0 0 0" xyz="0 0 0"/>
    <geometry>
      <mesh filename="package://manipulator_description/meshes/base_link.stl" scale="0.001 0.001 0.001"/>
    </geometry>
  </collision>
</link>

<link name="S3003_v5_1">
  <inertial>
    <origin rpy="0 0 0" xyz="0.005025153953305897 -0.0244276037446528 -0.008079731545445515"/>
    <mass value="0.23401442553734322"/>
    <inertia ixx="6e-05" ixy="0.0" ixz="-0.0" iyy="3.5e-05" iyz="-1e-06" izz="4e-05"/>
  </inertial>
  <visual>
    <origin rpy="0 0 0" xyz="0.005025 -0.0141 -0.003"/>
    <geometry>
      <mesh filename="package://manipulator_description/meshes/S3003_v5_1.stl" scale="0.001 0.001 0.001"/>
    </geometry>
    <material name="silver_default"/>
  </visual>
  <collision>
    <origin rpy="0 0 0" xyz="0.005025 -0.0141 -0.003"/>
    <geometry>
      <mesh filename="package://manipulator_description/meshes/S3003_v5_1.stl" scale="0.001 0.001 0.001"/>
    </geometry>
  </collision>
</link>

<link name="bottom_linkz_v4_1">
  <inertial>
    <origin rpy="0 0 0" xyz="1.8717896266100833e-05 1.8896593900124548e-05 0.01098031893511145"/>
    <mass value="0.19906890879785208"/>
    <inertia ixx="6.9e-05" ixy="0.0" ixz="-0.0" iyy="0.000123" iyz="-0.0" izz="0.000154"/>
  </inertial>
  <visual>
    <origin rpy="0 0 0" xyz="-0.0 0.0 -0.01919"/>
    <geometry>
      <mesh filename="package://manipulator_description/meshes/bottom_linkz_v4_1.stl" scale="0.001 0.001 0.001"/>
    </geometry>
    <material name="silver_default"/>
  </visual>
  <collision>
    <origin rpy="0 0 0" xyz="-0.0 0.0 -0.01919"/>
    <geometry>
      <mesh filename="package://manipulator_description/meshes/bottom_linkz_v4_1.stl" scale="0.001 0.001 0.001"/>
    </geometry>
  </collision>
</link>

<link name="S3003_v5_2">
  <inertial>
    <origin rpy="0 0 0" xyz="-0.024427603744652797 -0.008079731545445518 -0.005024846046694113"/>
    <mass value="0.23401442553734322"/>
    <inertia ixx="3.5e-05" ixy="-1e-06" ixz="0.0" iyy="4e-05" iyz="-0.0" izz="6e-05"/>
  </inertial>
  <visual>
    <origin rpy="0 0 0" xyz="-0.02425 -0.01 -0.04719"/>
    <geometry>
      <mesh filename="package://manipulator_description/meshes/S3003_v5_2.stl" scale="0.001 0.001 0.001"/>
    </geometry>
    <material name="silver_default"/>
  </visual>
  <collision>
    <origin rpy="0 0 0" xyz="-0.02425 -0.01 -0.04719"/>
    <geometry>
      <mesh filename="package://manipulator_description/meshes/S3003_v5_2.stl" scale="0.001 0.001 0.001"/>
    </geometry>
  </collision>
</link>

<link name="link_v3_1">
  <inertial>
    <origin rpy="0 0 0" xyz="-0.004835375618105062 -0.020157177647525597 0.04043657812083672"/>
    <mass value="0.14389975561434148"/>
    <inertia ixx="0.000157" ixy="-1e-06" ixz="8e-06" iyy="0.000114" iyz="6e-06" izz="6e-05"/>
  </inertial>
  <visual>
    <origin rpy="0 0 0" xyz="-0.01015 -0.02619 -0.042165"/>
    <geometry>
      <mesh filename="package://manipulator_description/meshes/link_v3_1.stl" scale="0.001 0.001 0.001"/>
    </geometry>
    <material name="silver_default"/>
  </visual>
  <collision>
    <origin rpy="0 0 0" xyz="-0.01015 -0.02619 -0.042165"/>
    <geometry>
      <mesh filename="package://manipulator_description/meshes/link_v3_1.stl" scale="0.001 0.001 0.001"/>
    </geometry>
  </collision>
</link>

<joint name="Rigid1" type="fixed">
  <origin rpy="0 0 0" xyz="-0.005025 0.0141 0.003"/>
  <parent link="base_link"/>
  <child link="S3003_v5_1"/>
</joint>

<joint name="Rev2" type="continuous">
  <origin rpy="0 0 0" xyz="0.005025 -0.0141 0.01619"/>
  <parent link="S3003_v5_1"/>
  <child link="bottom_linkz_v4_1"/>
  <axis xyz="0.0 -0.0 1.0"/>
</joint>

<joint name="Rigid3" type="fixed">
  <origin rpy="0 0 0" xyz="0.02425 0.01 0.028"/>
  <parent link="bottom_linkz_v4_1"/>
  <child link="S3003_v5_2"/>
</joint>

<joint name="Rev4" type="continuous">
  <origin rpy="0 0 0" xyz="-0.0141 0.01619 -0.005025"/>
  <parent link="S3003_v5_2"/>
  <child link="link_v3_1"/>
  <axis xyz="-0.0 1.0 0.0"/>
</joint>

</robot>
